Workbook

Sheet IRR inputs & outputs
A1: Model inputs | D1: Reference values | E1: AC single port 22kW | F1: AC dual port 22kW | G1: DC dual port 40kW
A2: Charger rated capacity (kW) | B2: 22 | E2: 22 | F2: 22 | G2: 40
A3: Number of ports | B3: 1 | E3: 1 | F3: 2 | G3: 2
A4: Capex | B4: 5000 | E4: 5000 | F4: 30000 | G4: 50000
A5: Capex subsidy | B5: 1 | G5: 0
A6: Post subsidy Capex | B6: =B4*(1-B5) -> 0 | E6: =E4*(1-E5) -> 5000 | F6: =F4*(1-F5) -> 30000 | G6: =G4*(1-G5) -> 50000
A7: Charger average power (% of rated capacity) | B7: 0.51 | E7: 0.51 | F7: 0.51 | G7: 0.62
A8: Charger efficiency (%) | B8: 0.95 | E8: 0.95 | F8: 0.95 | G8: 0.95
A9: Per unit electricity costs ($/kWh) | B9: 0.2 | E9: 0.2 | F9: 0.2 | G9: 0.2
A10: Fixed electricity costs ($ p.a.) | G10: 0
A11: Per unit software costs (% of revenue) | B11: 0.075 | E11: 0.075 | F11: 0.075 | G11: 0.075
A12: Fixed software costs ($ p.a.) | B12: 300 | E12: 300 | F12: 600 | G12: 600
A13: Sale price ($/kWh) | B13: 0.45 | E13: 0.45 | F13: 0.45 | G13: 0.55
A14: Maintenance ($ p.a.) | B14: 500 | E14: 500 | F14: 500 | G14: 750
A15: Replacement capex ($ in year 5) | B15: 3000 | E15: 3000 | F15: 3000 | G15: 35000
A16: Establishment fee to council (one off) | B16: 500 | E16: 500 | F16: 500 | G16: 1000
A17: Parking license fee to council or Ausgrid ($ p.a.) | B17: 750 | E17: 750 | F17: 800 | G17: 5000
A18: DNSP regulated return rate (WACC) | B18: 0.0585
A19: Commercial hurdle rate | B19: 0.12
A22: Model outputs
A23: Utilisation | B23: 0.05 | C23: 0.075 | D23: 0.1 | E23: 0.125 | F23: 0.15 | G23: 0.175 | H23: 0.2 | I23: 0.225 | J23: 0.25 | K23: 0.3 | L23: 0.35 | M23: 0.4 | N23: 0.45 | O23: 0.5
A24: IRR | B24: ='5% utilisation'!B23 -> #N/A | C24: ='7.5% utilisation'!B23 -> #N/A | D24: ='10% utilisation'!B23 -> 0.58195842 | E24: ='12.5% utilisation'!B23 -> 1.8993305 | F24: ='15% utilisation'!B23 -> 2.9475492 | G24: ='17.5% utilisation'!B23 -> 3.9691409 | H24: ='20% utilisation'!B23 -> 4.9841048 | I24: ='22.5% utilisation'!B23 -> 5.9968565 | J24: ='25% utilisation'!B23 -> 7.0087261 | K24: ='30% utilisation'!B23 -> 9.0314695 | L24: ='35% utilisation'!B23 -> 11.053743 | M24: ='40% utilisation'!B23 -> 13.075862 | N24: ='45% utilisation'!B23 -> 15.097921 | O24: ='50% utilisation'!B23 -> 17.119952
A25: Net income p.a. | B25: ='5% utilisation'!C21 -> -538.99976 | C25: ='7.5% utilisation'!C21 -> -33.499633 | D25: ='10% utilisation'!C21 -> 472.00049 | E25: ='12.5% utilisation'!C21 -> 977.50061 | F25: ='15% utilisation'!C21 -> 1483.0007 | G25: ='17.5% utilisation'!C21 -> 1988.5009 | H25: ='20% utilisation'!C21 -> 2494.001 | I25: ='22.5% utilisation'!C21 -> 2999.5011 | J25: ='25% utilisation'!C21 -> 3505.0012 | K25: ='30% utilisation'!C21 -> 4516.0015 | L25: ='35% utilisation'!C21 -> 5527.0017 | M25: ='40% utilisation'!C21 -> 6538.002 | N25: ='45% utilisation'!C21 -> 7549.0022 | O25: ='50% utilisation'!C21 -> 8560.0024
A26: NSP regulated return | B26: =$B$18 -> 0.0585 | C26: =$B$18 -> 0.0585 | D26: =$B$18 -> 0.0585 | E26: =$B$18 -> 0.0585 | F26: =$B$18 -> 0.0585 | G26: =$B$18 -> 0.0585 | H26: =$B$18 -> 0.0585 | I26: =$B$18 -> 0.0585 | ... O26: =$B$18 -> 0.0585
A27: Commercial hurdle rate | B27: =$B$19 -> 0.12 | C27: =$B$19 -> 0.12 | D27: =$B$19 -> 0.12 | E27: =$B$19 -> 0.12 | F27: =$B$19 -> 0.12 | G27: =$B$19 -> 0.12 | H27: =$B$19 -> 0.12 | I27: =$B$19 -> 0.12 | ... O27: =$B$19 -> 0.12
A29: Subsidy % DNSP | B29: ='5% utilisation'!$B$125 -> #N/A | C29: ='7.5% utilisation'!$B$125 -> #N/A | D29: ='10% utilisation'!$B$125 -> #N/A | E29: ='12.5% utilisation'!$B$125 -> #N/A | F29: ='15% utilisation'!$B$125 -> #N/A | G29: ='17.5% utilisation'!$B$125 -> #N/A | H29: ='20% utilisation'!$B$125 -> #N/A | I29: ='22.5% utilisation'!$B$125 -> #N/A | J29: ='25% utilisation'!$B$125 -> #N/A | K29: ='30% utilisation'!$B$125 -> #N/A | L29: ='35% utilisation'!$B$125 -> #N/A | M29: ='40% utilisation'!$B$125 -> #N/A | N29: ='45% utilisation'!$B$125 -> #N/A | O29: ='50% utilisation'!$B$125 -> #N/A
A30: Subsidy % CPO | B30: ='5% utilisation'!$B$126 -> #N/A | C30: ='7.5% utilisation'!$B$126 -> #N/A | D30: ='10% utilisation'!$B$126 -> #N/A | E30: ='12.5% utilisation'!$B$126 -> #N/A | F30: ='15% utilisation'!$B$126 -> #N/A | G30: ='17.5% utilisation'!$B$126 -> #N/A | H30: ='20% utilisation'!$B$126 -> #N/A | I30: ='22.5% utilisation'!$B$126 -> #N/A | J30: ='25% utilisation'!$B$126 -> #N/A | K30: ='30% utilisation'!$B$126 -> #N/A | L30: ='35% utilisation'!$B$126 -> #N/A | M30: ='40% utilisation'!$B$126 -> #N/A | N30: ='45% utilisation'!$B$126 -> #N/A | O30: ='50% utilisation'!$B$126 -> #N/A
A31: Retailer costs | B31: =SUM('5% utilisation'!$C$16:$G$18) -> 7502.3088 | C31: =SUM('7.5% utilisation'!$C$16:$G$18) -> 10503.463 | D31: =SUM('10% utilisation'!$C$16:$G$18) -> 13504.618 | E31: =SUM('12.5% utilisation'!$C$16:$G$18) -> 16505.772 | F31: =SUM('15% utilisation'!$C$16:$G$18) -> 19506.926 | G31: =SUM('17.5% utilisation'!$C$16:$G$18) -> 22508.081 | H31: =SUM('20% utilisation'!$C$16:$G$18) -> 25509.235
A32: DNSP opex | B32: =SUM('5% utilisation'!$C$14:$G$15) -> 6250 | C32: =SUM('7.5% utilisation'!$C$14:$G$15) -> 6250 | D32: =SUM('10% utilisation'!$C$14:$G$15) -> 6250 | E32: =SUM('12.5% utilisation'!$C$14:$G$15) -> 6250 | F32: =SUM('15% utilisation'!$C$14:$G$15) -> 6250 | G32: =SUM('17.5% utilisation'!$C$14:$G$15) -> 6250 | H32: =SUM('20% utilisation'!$C$14:$G$15) -> 6250
A33: Revenue | B33: =SUM('5% utilisation'!$C$9:$G$9) -> 11057.31 | C33: =SUM('5% utilisation'!$C$9:$G$9) -> 11057.31 | D33: =SUM('10% utilisation'!$C$9:$G$9) -> 22114.62 | E33: =SUM('12.5% utilisation'!$C$9:$G$9) -> 27643.275 | F33: =SUM('5% utilisation'!$C$9:$G$9) -> 11057.31 | G33: =SUM('17.5% utilisation'!$C$9:$G$9) -> 38700.585 | H33: =SUM('20% utilisation'!$C$9:$G$9) -> 44229.24

Sheet Bar chart
A1: AC 22kW dual port - 10% utilisation
A2: Subsidy % | B2: 0.3
A3: Taxpayer subsidy | B3: =1*B4*B2 -> 1155
A4: Capex | B4: =('IRR inputs & outputs'!B4+'IRR inputs & outputs'!B16)*(1-B2) -> 3850
A5: DNSP opex | B5: =1*('IRR inputs & outputs'!D32) -> 6250
A6: Retailer opex | B6: =1*('IRR inputs & outputs'!D31) -> 13504.618
A7: Revenue to retailer | C7: =B6*1.1 -> 14855.079
A8: DNSP revenue potential or benefit to EV drivers | C8: =C10-C7 -> 7259.5407
A10: Revenue (current pricing) | C10: ='IRR inputs & outputs'!D33 -> 22114.62

Sheet 5% utilisation
A1: Utilisation | B1: 0.05
A2: Hours in year | B2: =24*365 -> 8760
A3: Energy delivered | B3: =B2*B1*'IRR inputs & outputs'!B2*'IRR inputs & outputs'!B3*'IRR inputs & outputs'!$B$7 -> 4914.36 | C3: kWh p.a.
A5: Year | B5: 0 | C5: 1 | D5: 2 | E5: 3 | F5: 4 | G5: 5 | H5: 6 | I5: 7 | J5: 8 | K5: 9 | L5: 10
A6: Income
A7: Charging | C7: =$B$3*'IRR inputs & outputs'!$B$13 -> 2211.462 | D7: =$B$3*'IRR inputs & outputs'!$B$13 -> 2211.462 | E7: =$B$3*'IRR inputs & outputs'!$B$13 -> 2211.462 | F7: =$B$3*'IRR inputs & outputs'!$B$13 -> 2211.462 | G7: =$B$3*'IRR inputs & outputs'!$B$13 -> 2211.462 | H7: =$B$3*'IRR inputs & outputs'!$B$13 -> 2211.462 | I7: =$B$3*'IRR inputs & outputs'!$B$13 -> 2211.462 | J7: =$B$3*'IRR inputs & outputs'!$B$13 -> 2211.462 | ... L7: =$B$3*'IRR inputs & outputs'!$B$13 -> 2211.462
A9: Total income | C9: =SUM(C7:C8) -> 2211.462 | D9: =SUM(D7:D8) -> 2211.462 | E9: =SUM(E7:E8) -> 2211.462 | F9: =SUM(F7:F8) -> 2211.462 | G9: =SUM(G7:G8) -> 2211.462 | H9: =SUM(H7:H8) -> 2211.462 | I9: =SUM(I7:I8) -> 2211.462 | J9: =SUM(J7:J8) -> 2211.462 | ... L9: =SUM(L7:L8) -> 2211.462
A11: Outgoing
A12: Capex | B12: ='IRR inputs & outputs'!B6 -> 0 | G12: ='IRR inputs & outputs'!B15 -> 3000
A13: Site establishment | B13: ='IRR inputs & outputs'!B16 -> 500
A14: Site license | C14: ='IRR inputs & outputs'!$B$17 -> 750 | D14: ='IRR inputs & outputs'!$B$17 -> 750 | E14: ='IRR inputs & outputs'!$B$17 -> 750 | F14: ='IRR inputs & outputs'!$B$17 -> 750 | G14: ='IRR inputs & outputs'!$B$17 -> 750 | H14: ='IRR inputs & outputs'!$B$17 -> 750 | I14: ='IRR inputs & outputs'!$B$17 -> 750 | J14: ='IRR inputs & outputs'!$B$17 -> 750 | ... L14: ='IRR inputs & outputs'!$B$17 -> 750
A15: Maintenance | C15: ='IRR inputs & outputs'!B14 -> 500 | D15: ='IRR inputs & outputs'!B14 -> 500 | E15: ='IRR inputs & outputs'!B14 -> 500 | F15: ='IRR inputs & outputs'!B14 -> 500 | G15: ='IRR inputs & outputs'!B14 -> 500 | H15: ='IRR inputs & outputs'!B14 -> 500 | I15: ='IRR inputs & outputs'!B14 -> 500 | J15: ='IRR inputs & outputs'!B14 -> 500 | K15: ='IRR inputs & outputs'!B14 -> 500 | L15: ='IRR inputs & outputs'!B14 -> 500
A16: Electricity | C16: =(1/'IRR inputs & outputs'!$B$8)*$B$3*'IRR inputs & outputs'!$B$9+'IRR inputs & outputs'!$B$10 -> 1034.6021 | D16: =(1/'IRR inputs & outputs'!$B$8)*$B$3*'IRR inputs & outputs'!$B$9+'IRR inputs & outputs'!$B$10 -> 1034.6021 | E16: =(1/'IRR inputs & outputs'!$B$8)*$B$3*'IRR inputs & outputs'!$B$9+'IRR inputs & outputs'!$B$10 -> 1034.6021 | F16: =(1/'IRR inputs & outputs'!$B$8)*$B$3*'IRR inputs & outputs'!$B$9+'IRR inputs & outputs'!$B$10 -> 1034.6021 | G16: =(1/'IRR inputs & outputs'!$B$8)*$B$3*'IRR inputs & outputs'!$B$9+'IRR inputs & outputs'!$B$10 -> 1034.6021 | H16: =(1/'IRR inputs & outputs'!$B$8)*$B$3*'IRR inputs & outputs'!$B$9+'IRR inputs & outputs'!$B$10 -> 1034.6021 | I16: =(1/'IRR inputs & outputs'!$B$8)*$B$3*'IRR inputs & outputs'!$B$9+'IRR inputs & outputs'!$B$10 -> 1034.6021 | J16: =(1/'IRR inputs & outputs'!$B$8)*$B$3*'IRR inputs & outputs'!$B$9+'IRR inputs & outputs'!$B$10 -> 1034.6021 | ... L16: =(1/'IRR inputs & outputs'!$B$8)*$B$3*'IRR inputs & outputs'!$B$9+'IRR inputs & outputs'!$B$10 -> 1034.6021
A17: Software - fixed | C17: ='IRR inputs & outputs'!$B$12 -> 300 | D17: ='IRR inputs & outputs'!$B$12 -> 300 | E17: ='IRR inputs & outputs'!$B$12 -> 300 | F17: ='IRR inputs & outputs'!$B$12 -> 300 | G17: ='IRR inputs & outputs'!$B$12 -> 300 | H17: ='IRR inputs & outputs'!$B$12 -> 300 | I17: ='IRR inputs & outputs'!$B$12 -> 300 | J17: ='IRR inputs & outputs'!$B$12 -> 300 | ... L17: ='IRR inputs & outputs'!$B$12 -> 300
A18: Software - variable | C18: =$B$3*'IRR inputs & outputs'!$B$11*'IRR inputs & outputs'!$B$13 -> 165.85965 | D18: =$B$3*'IRR inputs & outputs'!$B$11*'IRR inputs & outputs'!$B$13 -> 165.85965 | E18: =$B$3*'IRR inputs & outputs'!$B$11*'IRR inputs & outputs'!$B$13 -> 165.85965 | F18: =$B$3*'IRR inputs & outputs'!$B$11*'IRR inputs & outputs'!$B$13 -> 165.85965 | G18: =$B$3*'IRR inputs & outputs'!$B$11*'IRR inputs & outputs'!$B$13 -> 165.85965 | H18: =$B$3*'IRR inputs & outputs'!$B$11*'IRR inputs & outputs'!$B$13 -> 165.85965 | I18: =$B$3*'IRR inputs & outputs'!$B$11*'IRR inputs & outputs'!$B$13 -> 165.85965 | J18: =$B$3*'IRR inputs & outputs'!$B$11*'IRR inputs & outputs'!$B$13 -> 165.85965 | ... L18: =$B$3*'IRR inputs & outputs'!$B$11*'IRR inputs & outputs'!$B$13 -> 165.85965
A19: Total outgoings | B19: =SUM(B12:B18) -> 500 | C19: =SUM(C12:C18) -> 2750.4618 | D19: =SUM(D12:D18) -> 2750.4618 | E19: =SUM(E12:E18) -> 2750.4618 | F19: =SUM(F12:F18) -> 2750.4618 | G19: =SUM(G12:G18) -> 5750.4618 | H19: =SUM(H12:H18) -> 2750.4618 | I19: =SUM(I12:I18) -> 2750.4618 | ... L19: =SUM(L12:L18) -> 2750.4618
A21: Total | B21: =B9-B19 -> -500 | C21: =C9-C19 -> -538.99976 | D21: =D9-D19 -> -538.99976 | E21: =E9-E19 -> -538.99976 | F21: =F9-F19 -> -538.99976 | G21: =G9-G19 -> -3538.9998 | H21: =H9-H19 -> -538.99976 | I21: =I9-I19 -> -538.99976 | ... L21: =L9-L19 -> -538.99976
A23: IRR | B23: =IFERROR(IRR(B21:L21),NA()) -> #N/A
A25: Subsidy effect
A26: Subsidy | B26: 0.1
A27: Subsidised capex | B27: =$B$12*(1-B26) -> 0
A28: Cashflow | B28: =-B27 -> 0 | C28: =$C$21 -> -538.99976 | D28: =$D$21 -> -538.99976 | E28: =$E$21 -> -538.99976 | F28: =$F$21 -> -538.99976 | G28: =$G$21 -> -3538.9998 | H28: =$H$21 -> -538.99976 | I28: =$I$21 -> -538.99976 | J28: =$J$21 -> -538.99976 | K28: =$K$21 -> -538.99976 | L28: =$L$21 -> -538.99976
A29: IRR | B29: =IFERROR(IRR(B28:L28),NA()) -> #N/A
A31: Subsidy | B31: 0.15
A32: Subsidised capex | B32: =$B$12*(1-B31) -> 0
A33: Cashflow | B33: =-B32 -> 0 | C33: =$C$21 -> -538.99976 | D33: =$D$21 -> -538.99976 | E33: =$E$21 -> -538.99976 | F33: =$F$21 -> -538.99976 | G33: =$G$21 -> -3538.9998 | H33: =$H$21 -> -538.99976 | I33: =$I$21 -> -538.99976 | J33: =$J$21 -> -538.99976 | K33: =$K$21 -> -538.99976 | L33: =$L$21 -> -538.99976
A34: IRR | B34: =IFERROR(IRR(B33:L33),NA()) -> #N/A
A36: Subsidy | B36: 0.2
A37: Subsidised capex | B37: =$B$12*(1-B36) -> 0
A38: Cashflow | B38: =-B37 -> 0 | C38: =$C$21 -> -538.99976 | D38: =$D$21 -> -538.99976 | E38: =$E$21 -> -538.99976 | F38: =$F$21 -> -538.99976 | G38: =$G$21 -> -3538.9998 | H38: =$H$21 -> -538.99976 | I38: =$I$21 -> -538.99976 | J38: =$J$21 -> -538.99976 | K38: =$K$21 -> -538.99976 | L38: =$L$21 -> -538.99976
A39: IRR | B39: =IFERROR(IRR(B38:L38),NA()) -> #N/A
A41: Subsidy | B41: 0.25
A42: Subsidised capex | B42: =$B$12*(1-B41) -> 0
A43: Cashflow | B43: =-B42 -> 0 | C43: =$C$21 -> -538.99976 | D43: =$D$21 -> -538.99976 | E43: =$E$21 -> -538.99976 | F43: =$F$21 -> -538.99976 | G43: =$G$21 -> -3538.9998 | H43: =$H$21 -> -538.99976 | I43: =$I$21 -> -538.99976 | J43: =$J$21 -> -538.99976 | K43: =$K$21 -> -538.99976 | L43: =$L$21 -> -538.99976
A44: IRR | B44: =IFERROR(IRR(B43:L43),NA()) -> #N/A
A46: Subsidy | B46: 0.3
A47: Subsidised capex | B47: =$B$12*(1-B46) -> 0
A48: Cashflow | B48: =-B47 -> 0 | C48: =$C$21 -> -538.99976 | D48: =$D$21 -> -538.99976 | E48: =$E$21 -> -538.99976 | F48: =$F$21 -> -538.99976 | G48: =$G$21 -> -3538.9998 | H48: =$H$21 -> -538.99976 | I48: =$I$21 -> -538.99976 | J48: =$J$21 -> -538.99976 | K48: =$K$21 -> -538.99976 | L48: =$L$21 -> -538.99976
A49: IRR | B49: =IFERROR(IRR(B48:L48),NA()) -> #N/A
A51: Subsidy | B51: 0.35
...

Sheet 7.5% utilisation
A1: Utilisation | B1: 0.075
A2: Hours in year | B2: =24*365 -> 8760
A3: Energy delivered | B3: =B2*B1*'IRR inputs & outputs'!B2*'IRR inputs & outputs'!B3*'IRR inputs & outputs'!$B$7 -> 7371.54 | C3: kWh p.a.
A5: Year | B5: 0 | C5: 1 | D5: 2 | E5: 3 | F5: 4 | G5: 5 | H5: 6 | I5: 7 | J5: 8 | K5: 9 | L5: 10
A6: Income
A7: Charging | C7: =$B$3*'IRR inputs & outputs'!$B$13 -> 3317.193 | D7: =$B$3*'IRR inputs & outputs'!$B$13 -> 3317.193 | E7: =$B$3*'IRR inputs & outputs'!$B$13 -> 3317.193 | F7: =$B$3*'IRR inputs & outputs'!$B$13 -> 3317.193 | G7: =$B$3*'IRR inputs & outputs'!$B$13 -> 3317.193 | H7: =$B$3*'IRR inputs & outputs'!$B$13 -> 3317.193 | I7: =$B$3*'IRR inputs & outputs'!$B$13 -> 3317.193 | J7: =$B$3*'IRR inputs & outputs'!$B$13 -> 3317.193 | ... L7: =$B$3*'IRR inputs & outputs'!$B$13 -> 3317.193
A9: Total income | C9: =SUM(C7:C8) -> 3317.193 | D9: =SUM(D7:D8) -> 3317.193 | E9: =SUM(E7:E8) -> 3317.193 | F9: =SUM(F7:F8) -> 3317.193 | G9: =SUM(G7:G8) -> 3317.193 | H9: =SUM(H7:H8) -> 3317.193 | I9: =SUM(I7:I8) -> 3317.193 | J9: =SUM(J7:J8) -> 3317.193 | ... L9: =SUM(L7:L8) -> 3317.193
A11: Outgoing
A12: Capex | B12: ='IRR inputs & outputs'!B6 -> 0 | G12: ='IRR inputs & outputs'!B15 -> 3000
A13: Site establishment | B13: ='IRR inputs & outputs'!B16 -> 500
A14: Site license | C14: ='IRR inputs & outputs'!$B$17 -> 750 | D14: ='IRR inputs & outputs'!$B$17 -> 750 | E14: ='IRR inputs & outputs'!$B$17 -> 750 | F14: ='IRR inputs & outputs'!$B$17 -> 750 | G14: ='IRR inputs & outputs'!$B$17 -> 750 | H14: ='IRR inputs & outputs'!$B$17 -> 750 | I14: ='IRR inputs & outputs'!$B$17 -> 750 | J14: ='IRR inputs & outputs'!$B$17 -> 750 | ... L14: ='IRR inputs & outputs'!$B$17 -> 750
A15: Maintenance | C15: ='IRR inputs & outputs'!B14 -> 500 | D15: ='IRR inputs & outputs'!B14 -> 500 | E15: ='IRR inputs & outputs'!B14 -> 500 | F15: ='IRR inputs & outputs'!B14 -> 500 | G15: ='IRR inputs & outputs'!B14 -> 500 | H15: ='IRR inputs & outputs'!B14 -> 500 | I15: ='IRR inputs & outputs'!B14 -> 500 | J15: ='IRR inputs & outputs'!B14 -> 500 | K15: ='IRR inputs & outputs'!B14 -> 500 | L15: ='IRR inputs & outputs'!B14 -> 500
A16: Electricity | C16: =(1/'IRR inputs & outputs'!$B$8)*$B$3*'IRR inputs & outputs'!$B$9+'IRR inputs & outputs'!$B$10 -> 1551.9032 | D16: =(1/'IRR inputs & outputs'!$B$8)*$B$3*'IRR inputs & outputs'!$B$9+'IRR inputs & outputs'!$B$10 -> 1551.9032 | E16: =(1/'IRR inputs & outputs'!$B$8)*$B$3*'IRR inputs & outputs'!$B$9+'IRR inputs & outputs'!$B$10 -> 1551.9032 | F16: =(1/'IRR inputs & outputs'!$B$8)*$B$3*'IRR inputs & outputs'!$B$9+'IRR inputs & outputs'!$B$10 -> 1551.9032 | G16: =(1/'IRR inputs & outputs'!$B$8)*$B$3*'IRR inputs & outputs'!$B$9+'IRR inputs & outputs'!$B$10 -> 1551.9032 | H16: =(1/'IRR inputs & outputs'!$B$8)*$B$3*'IRR inputs & outputs'!$B$9+'IRR inputs & outputs'!$B$10 -> 1551.9032 | I16: =(1/'IRR inputs & outputs'!$B$8)*$B$3*'IRR inputs & outputs'!$B$9+'IRR inputs & outputs'!$B$10 -> 1551.9032 | J16: =(1/'IRR inputs & outputs'!$B$8)*$B$3*'IRR inputs & outputs'!$B$9+'IRR inputs & outputs'!$B$10 -> 1551.9032 | ... L16: =(1/'IRR inputs & outputs'!$B$8)*$B$3*'IRR inputs & outputs'!$B$9+'IRR inputs & outputs'!$B$10 -> 1551.9032
A17: Software - fixed | C17: ='IRR inputs & outputs'!$B$12 -> 300 | D17: ='IRR inputs & outputs'!$B$12 -> 300 | E17: ='IRR inputs & outputs'!$B$12 -> 300 | F17: ='IRR inputs & outputs'!$B$12 -> 300 | G17: ='IRR inputs & outputs'!$B$12 -> 300 | H17: ='IRR inputs & outputs'!$B$12 -> 300 | I17: ='IRR inputs & outputs'!$B$12 -> 300 | J17: ='IRR inputs & outputs'!$B$12 -> 300 | ... L17: ='IRR inputs & outputs'!$B$12 -> 300
A18: Software - variable | C18: =$B$3*'IRR inputs & outputs'!$B$11*'IRR inputs & outputs'!$B$13 -> 248.78948 | D18: =$B$3*'IRR inputs & outputs'!$B$11*'IRR inputs & outputs'!$B$13 -> 248.78948 | E18: =$B$3*'IRR inputs & outputs'!$B$11*'IRR inputs & outputs'!$B$13 -> 248.78948 | F18: =$B$3*'IRR inputs & outputs'!$B$11*'IRR inputs & outputs'!$B$13 -> 248.78948 | G18: =$B$3*'IRR inputs & outputs'!$B$11*'IRR inputs & outputs'!$B$13 -> 248.78948 | H18: =$B$3*'IRR inputs & outputs'!$B$11*'IRR inputs & outputs'!$B$13 -> 248.78948 | I18: =$B$3*'IRR inputs & outputs'!$B$11*'IRR inputs & outputs'!$B$13 -> 248.78948 | J18: =$B$3*'IRR inputs & outputs'!$B$11*'IRR inputs & outputs'!$B$13 -> 248.78948 | ... L18: =$B$3*'IRR inputs & outputs'!$B$11*'IRR inputs & outputs'!$B$13 -> 248.78948
A19: Total outgoings | B19: =SUM(B12:B18) -> 500 | C19: =SUM(C12:C18) -> 3350.6926 | D19: =SUM(D12:D18) -> 3350.6926 | E19: =SUM(E12:E18) -> 3350.6926 | F19: =SUM(F12:F18) -> 3350.6926 | G19: =SUM(G12:G18) -> 6350.6926 | H19: =SUM(H12:H18) -> 3350.6926 | I19: =SUM(I12:I18) -> 3350.6926 | ... L19: =SUM(L12:L18) -> 3350.6926
A21: Total | B21: =B9-B19 -> -500 | C21: =C9-C19 -> -33.499633 | D21: =D9-D19 -> -33.499633 | E21: =E9-E19 -> -33.499633 | F21: =F9-F19 -> -33.499633 | G21: =G9-G19 -> -3033.4996 | H21: =H9-H19 -> -33.499633 | I21: =I9-I19 -> -33.499633 | ... L21: =L9-L19 -> -33.499633
A23: IRR | B23: =IFERROR(IRR(B21:L21),NA()) -> #N/A
A25: Subsidy effect
A26: Subsidy | B26: 0.1
A27: Subsidised capex | B27: =$B$12*(1-B26) -> 0
A28: Cashflow | B28: =-B27 -> 0 | C28: =$C$21 -> -33.499633 | D28: =$D$21 -> -33.499633 | E28: =$E$21 -> -33.499633 | F28: =$F$21 -> -33.499633 | G28: =$G$21 -> -3033.4996 | H28: =$H$21 -> -33.499633 | I28: =$I$21 -> -33.499633 | J28: =$J$21 -> -33.499633 | K28: =$K$21 -> -33.499633 | L28: =$L$21 -> -33.499633
A29: IRR | B29: =IFERROR(IRR(B28:L28),NA()) -> #N/A
A31: Subsidy | B31: 0.15
A32: Subsidised capex | B32: =$B$12*(1-B31) -> 0
A33: Cashflow | B33: =-B32 -> 0 | C33: =$C$21 -> -33.499633 | D33: =$D$21 -> -33.499633 | E33: =$E$21 -> -33.499633 | F33: =$F$21 -> -33.499633 | G33: =$G$21 -> -3033.4996 | H33: =$H$21 -> -33.499633 | I33: =$I$21 -> -33.499633 | J33: =$J$21 -> -33.499633 | K33: =$K$21 -> -33.499633 | L33: =$L$21 -> -33.499633
A34: IRR | B34: =IFERROR(IRR(B33:L33),NA()) -> #N/A
A36: Subsidy | B36: 0.2
A37: Subsidised capex | B37: =$B$12*(1-B36) -> 0
A38: Cashflow | B38: =-B37 -> 0 | C38: =$C$21 -> -33.499633 | D38: =$D$21 -> -33.499633 | E38: =$E$21 -> -33.499633 | F38: =$F$21 -> -33.499633 | G38: =$G$21 -> -3033.4996 | H38: =$H$21 -> -33.499633 | I38: =$I$21 -> -33.499633 | J38: =$J$21 -> -33.499633 | K38: =$K$21 -> -33.499633 | L38: =$L$21 -> -33.499633
A39: IRR | B39: =IFERROR(IRR(B38:L38),NA()) -> #N/A
A41: Subsidy | B41: 0.25
A42: Subsidised capex | B42: =$B$12*(1-B41) -> 0
A43: Cashflow | B43: =-B42 -> 0 | C43: =$C$21 -> -33.499633 | D43: =$D$21 -> -33.499633 | E43: =$E$21 -> -33.499633 | F43: =$F$21 -> -33.499633 | G43: =$G$21 -> -3033.4996 | H43: =$H$21 -> -33.499633 | I43: =$I$21 -> -33.499633 | J43: =$J$21 -> -33.499633 | K43: =$K$21 -> -33.499633 | L43: =$L$21 -> -33.499633
A44: IRR | B44: =IFERROR(IRR(B43:L43),NA()) -> #N/A
A46: Subsidy | B46: 0.3
A47: Subsidised capex | B47: =$B$12*(1-B46) -> 0
A48: Cashflow | B48: =-B47 -> 0 | C48: =$C$21 -> -33.499633 | D48: =$D$21 -> -33.499633 | E48: =$E$21 -> -33.499633 | F48: =$F$21 -> -33.499633 | G48: =$G$21 -> -3033.4996 | H48: =$H$21 -> -33.499633 | I48: =$I$21 -> -33.499633 | J48: =$J$21 -> -33.499633 | K48: =$K$21 -> -33.499633 | L48: =$L$21 -> -33.499633
A49: IRR | B49: =IFERROR(IRR(B48:L48),NA()) -> #N/A
A51: Subsidy | B51: 0.35
...

Sheet 10% utilisation
A1: Utilisation | B1: 0.1
A2: Hours in year | B2: =24*365 -> 8760
A3: Energy delivered | B3: =B2*B1*'IRR inputs & outputs'!B2*'IRR inputs & outputs'!B3*'IRR inputs & outputs'!$B$7 -> 9828.72 | C3: kWh p.a.
A5: Year | B5: 0 | C5: 1 | D5: 2 | E5: 3 | F5: 4 | G5: 5 | H5: 6 | I5: 7 | J5: 8 | K5: 9 | L5: 10
A6: Income
A7: Charging | C7: =$B$3*'IRR inputs & outputs'!$B$13 -> 4422.924 | D7: =$B$3*'IRR inputs & outputs'!$B$13 -> 4422.924 | E7: =$B$3*'IRR inputs & outputs'!$B$13 -> 4422.924 | F7: =$B$3*'IRR inputs & outputs'!$B$13 -> 4422.924 | G7: =$B$3*'IRR inputs & outputs'!$B$13 -> 4422.924 | H7: =$B$3*'IRR inputs & outputs'!$B$13 -> 4422.924 | I7: =$B$3*'IRR inputs & outputs'!$B$13 -> 4422.924 | J7: =$B$3*'IRR inputs & outputs'!$B$13 -> 4422.924 | ... L7: =$B$3*'IRR inputs & outputs'!$B$13 -> 4422.924
A9: Total income | C9: =SUM(C7:C8) -> 4422.924 | D9: =SUM(D7:D8) -> 4422.924 | E9: =SUM(E7:E8) -> 4422.924 | F9: =SUM(F7:F8) -> 4422.924 | G9: =SUM(G7:G8) -> 4422.924 | H9: =SUM(H7:H8) -> 4422.924 | I9: =SUM(I7:I8) -> 4422.924 | J9: =SUM(J7:J8) -> 4422.924 | ... L9: =SUM(L7:L8) -> 4422.924
A11: Outgoing
A12: Capex | B12: ='IRR inputs & outputs'!B6 -> 0 | G12: ='IRR inputs & outputs'!B15 -> 3000
A13: Site establishment | B13: ='IRR inputs & outputs'!B16 -> 500
A14: Site license | C14: ='IRR inputs & outputs'!$B$17 -> 750 | D14: ='IRR inputs & outputs'!$B$17 -> 750 | E14: ='IRR inputs & outputs'!$B$17 -> 750 | F14: ='IRR inputs & outputs'!$B$17 -> 750 | G14: ='IRR inputs & outputs'!$B$17 -> 750 | H14: ='IRR inputs & outputs'!$B$17 -> 750 | I14: ='IRR inputs & outputs'!$B$17 -> 750 | J14: ='IRR inputs & outputs'!$B$17 -> 750 | ... L14: ='IRR inputs & outputs'!$B$17 -> 750
A15: Maintenance | C15: ='IRR inputs & outputs'!B14 -> 500 | D15: ='IRR inputs & outputs'!B14 -> 500 | E15: ='IRR inputs & outputs'!B14 -> 500 | F15: ='IRR inputs & outputs'!B14 -> 500 | G15: ='IRR inputs & outputs'!B14 -> 500 | H15: ='IRR inputs & outputs'!B14 -> 500 | I15: ='IRR inputs & outputs'!B14 -> 500 | J15: ='IRR inputs & outputs'!B14 -> 500 | K15: ='IRR inputs & outputs'!B14 -> 500 | L15: ='IRR inputs & outputs'!B14 -> 500
A16: Electricity | C16: =(1/'IRR inputs & outputs'!$B$8)*$B$3*'IRR inputs & outputs'!$B$9+'IRR inputs & outputs'!$B$10 -> 2069.2042 | D16: =(1/'IRR inputs & outputs'!$B$8)*$B$3*'IRR inputs & outputs'!$B$9+'IRR inputs & outputs'!$B$10 -> 2069.2042 | E16: =(1/'IRR inputs & outputs'!$B$8)*$B$3*'IRR inputs & outputs'!$B$9+'IRR inputs & outputs'!$B$10 -> 2069.2042 | F16: =(1/'IRR inputs & outputs'!$B$8)*$B$3*'IRR inputs & outputs'!$B$9+'IRR inputs & outputs'!$B$10 -> 2069.2042 | G16: =(1/'IRR inputs & outputs'!$B$8)*$B$3*'IRR inputs & outputs'!$B$9+'IRR inputs & outputs'!$B$10 -> 2069.2042 | H16: =(1/'IRR inputs & outputs'!$B$8)*$B$3*'IRR inputs & outputs'!$B$9+'IRR inputs & outputs'!$B$10 -> 2069.2042 | I16: =(1/'IRR inputs & outputs'!$B$8)*$B$3*'IRR inputs & outputs'!$B$9+'IRR inputs & outputs'!$B$10 -> 2069.2042 | J16: =(1/'IRR inputs & outputs'!$B$8)*$B$3*'IRR inputs & outputs'!$B$9+'IRR inputs & outputs'!$B$10 -> 2069.2042 | ... L16: =(1/'IRR inputs & outputs'!$B$8)*$B$3*'IRR inputs & outputs'!$B$9+'IRR inputs & outputs'!$B$10 -> 2069.2042
A17: Software - fixed | C17: ='IRR inputs & outputs'!$B$12 -> 300 | D17: ='IRR inputs & outputs'!$B$12 -> 300 | E17: ='IRR inputs & outputs'!$B$12 -> 300 | F17: ='IRR inputs & outputs'!$B$12 -> 300 | G17: ='IRR inputs & outputs'!$B$12 -> 300 | H17: ='IRR inputs & outputs'!$B$12 -> 300 | I17: ='IRR inputs & outputs'!$B$12 -> 300 | J17: ='IRR inputs & outputs'!$B$12 -> 300 | ... L17: ='IRR inputs & outputs'!$B$12 -> 300
A18: Software - variable | C18: =$B$3*'IRR inputs & outputs'!$B$11*'IRR inputs & outputs'!$B$13 -> 331.7193 | D18: =$B$3*'IRR inputs & outputs'!$B$11*'IRR inputs & outputs'!$B$13 -> 331.7193 | E18: =$B$3*'IRR inputs & outputs'!$B$11*'IRR inputs & outputs'!$B$13 -> 331.7193 | F18: =$B$3*'IRR inputs & outputs'!$B$11*'IRR inputs & outputs'!$B$13 -> 331.7193 | G18: =$B$3*'IRR inputs & outputs'!$B$11*'IRR inputs & outputs'!$B$13 -> 331.7193 | H18: =$B$3*'IRR inputs & outputs'!$B$11*'IRR inputs & outputs'!$B$13 -> 331.7193 | I18: =$B$3*'IRR inputs & outputs'!$B$11*'IRR inputs & outputs'!$B$13 -> 331.7193 | J18: =$B$3*'IRR inputs & outputs'!$B$11*'IRR inputs & outputs'!$B$13 -> 331.7193 | ... L18: =$B$3*'IRR inputs & outputs'!$B$11*'IRR inputs & outputs'!$B$13 -> 331.7193
A19: Total outgoings | B19: =SUM(B12:B18) -> 500 | C19: =SUM(C12:C18) -> 3950.9235 | D19: =SUM(D12:D18) -> 3950.9235 | E19: =SUM(E12:E18) -> 3950.9235 | F19: =SUM(F12:F18) -> 3950.9235 | G19: =SUM(G12:G18) -> 6950.9235 | H19: =SUM(H12:H18) -> 3950.9235 | I19: =SUM(I12:I18) -> 3950.9235 | ... L19: =SUM(L12:L18) -> 3950.9235
A21: Total | B21: =B9-B19 -> -500 | C21: =C9-C19 -> 472.00049 | D21: =D9-D19 -> 472.00049 | E21: =E9-E19 -> 472.00049 | F21: =F9-F19 -> 472.00049 | G21: =G9-G19 -> -2527.9995 | H21: =H9-H19 -> 472.00049 | I21: =I9-I19 -> 472.00049 | ... L21: =L9-L19 -> 472.00049
A23: IRR | B23: =IFERROR(IRR(B21:L21),NA()) -> 0.58195842
A25: Subsidy effect
A26: Subsidy | B26: 0.1
A27: Subsidised capex | B27: =$B$12*(1-B26) -> 0
A28: Cashflow | B28: =-B27 -> 0 | C28: =$C$21 -> 472.00049 | D28: =$D$21 -> 472.00049 | E28: =$E$21 -> 472.00049 | F28: =$F$21 -> 472.00049 | G28: =$G$21 -> -2527.9995 | H28: =$H$21 -> 472.00049 | I28: =$I$21 -> 472.00049 | J28: =$J$21 -> 472.00049 | K28: =$K$21 -> 472.00049 | L28: =$L$21 -> 472.00049
A29: IRR | B29: =IFERROR(IRR(B28:L28),NA()) -> #N/A
A31: Subsidy | B31: 0.15
A32: Subsidised capex | B32: =$B$12*(1-B31) -> 0
A33: Cashflow | B33: =-B32 -> 0 | C33: =$C$21 -> 472.00049 | D33: =$D$21 -> 472.00049 | E33: =$E$21 -> 472.00049 | F33: =$F$21 -> 472.00049 | G33: =$G$21 -> -2527.9995 | H33: =$H$21 -> 472.00049 | I33: =$I$21 -> 472.00049 | J33: =$J$21 -> 472.00049 | K33: =$K$21 -> 472.00049 | L33: =$L$21 -> 472.00049
A34: IRR | B34: =IFERROR(IRR(B33:L33),NA()) -> #N/A
A36: Subsidy | B36: 0.2
A37: Subsidised capex | B37: =$B$12*(1-B36) -> 0
A38: Cashflow | B38: =-B37 -> 0 | C38: =$C$21 -> 472.00049 | D38: =$D$21 -> 472.00049 | E38: =$E$21 -> 472.00049 | F38: =$F$21 -> 472.00049 | G38: =$G$21 -> -2527.9995 | H38: =$H$21 -> 472.00049 | I38: =$I$21 -> 472.00049 | J38: =$J$21 -> 472.00049 | K38: =$K$21 -> 472.00049 | L38: =$L$21 -> 472.00049
A39: IRR | B39: =IFERROR(IRR(B38:L38),NA()) -> #N/A
A41: Subsidy | B41: 0.25
A42: Subsidised capex | B42: =$B$12*(1-B41) -> 0
A43: Cashflow | B43: =-B42 -> 0 | C43: =$C$21 -> 472.00049 | D43: =$D$21 -> 472.00049 | E43: =$E$21 -> 472.00049 | F43: =$F$21 -> 472.00049 | G43: =$G$21 -> -2527.9995 | H43: =$H$21 -> 472.00049 | I43: =$I$21 -> 472.00049 | J43: =$J$21 -> 472.00049 | K43: =$K$21 -> 472.00049 | L43: =$L$21 -> 472.00049
A44: IRR | B44: =IFERROR(IRR(B43:L43),NA()) -> #N/A
A46: Subsidy | B46: 0.3
A47: Subsidised capex | B47: =$B$12*(1-B46) -> 0
A48: Cashflow | B48: =-B47 -> 0 | C48: =$C$21 -> 472.00049 | D48: =$D$21 -> 472.00049 | E48: =$E$21 -> 472.00049 | F48: =$F$21 -> 472.00049 | G48: =$G$21 -> -2527.9995 | H48: =$H$21 -> 472.00049 | I48: =$I$21 -> 472.00049 | J48: =$J$21 -> 472.00049 | K48: =$K$21 -> 472.00049 | L48: =$L$21 -> 472.00049
A49: IRR | B49: =IFERROR(IRR(B48:L48),NA()) -> #N/A
A51: Subsidy | B51: 0.35
...

Sheet 12.5% utilisation
A1: Utilisation | B1: 0.125
A2: Hours in year | B2: =24*365 -> 8760
A3: Energy delivered | B3: =B2*B1*'IRR inputs & outputs'!B2*'IRR inputs & outputs'!B3*'IRR inputs & outputs'!$B$7 -> 12285.9 | C3: kWh p.a.
A5: Year | B5: 0 | C5: 1 | D5: 2 | E5: 3 | F5: 4 | G5: 5 | H5: 6 | I5: 7 | J5: 8 | K5: 9 | L5: 10
A6: Income
A7: Charging | C7: =$B$3*'IRR inputs & outputs'!$B$13 -> 5528.655 | D7: =$B$3*'IRR inputs & outputs'!$B$13 -> 5528.655 | E7: =$B$3*'IRR inputs & outputs'!$B$13 -> 5528.655 | F7: =$B$3*'IRR inputs & outputs'!$B$13 -> 5528.655 | G7: =$B$3*'IRR inputs & outputs'!$B$13 -> 5528.655 | H7: =$B$3*'IRR inputs & outputs'!$B$13 -> 5528.655 | I7: =$B$3*'IRR inputs & outputs'!$B$13 -> 5528.655 | J7: =$B$3*'IRR inputs & outputs'!$B$13 -> 5528.655 | ... L7: =$B$3*'IRR inputs & outputs'!$B$13 -> 5528.655
A9: Total income | C9: =SUM(C7:C8) -> 5528.655 | D9: =SUM(D7:D8) -> 5528.655 | E9: =SUM(E7:E8) -> 5528.655 | F9: =SUM(F7:F8) -> 5528.655 | G9: =SUM(G7:G8) -> 5528.655 | H9: =SUM(H7:H8) -> 5528.655 | I9: =SUM(I7:I8) -> 5528.655 | J9: =SUM(J7:J8) -> 5528.655 | ... L9: =SUM(L7:L8) -> 5528.655
A11: Outgoing
A12: Capex | B12: ='IRR inputs & outputs'!B6 -> 0 | G12: ='IRR inputs & outputs'!B15 -> 3000
A13: Site establishment | B13: ='IRR inputs & outputs'!B16 -> 500
A14: Site license | C14: ='IRR inputs & outputs'!$B$17 -> 750 | D14: ='IRR inputs & outputs'!$B$17 -> 750 | E14: ='IRR inputs & outputs'!$B$17 -> 750 | F14: ='IRR inputs & outputs'!$B$17 -> 750 | G14: ='IRR inputs & outputs'!$B$17 -> 750 | H14: ='IRR inputs & outputs'!$B$17 -> 750 | I14: ='IRR inputs & outputs'!$B$17 -> 750 | J14: ='IRR inputs & outputs'!$B$17 -> 750 | ... L14: ='IRR inputs & outputs'!$B$17 -> 750
A15: Maintenance | C15: ='IRR inputs & outputs'!B14 -> 500 | D15: ='IRR inputs & outputs'!B14 -> 500 | E15: ='IRR inputs & outputs'!B14 -> 500 | F15: ='IRR inputs & outputs'!B14 -> 500 | G15: ='IRR inputs & outputs'!B14 -> 500 | H15: ='IRR inputs & outputs'!B14 -> 500 | I15: ='IRR inputs & outputs'!B14 -> 500 | J15: ='IRR inputs & outputs'!B14 -> 500 | K15: ='IRR inputs & outputs'!B14 -> 500 | L15: ='IRR inputs & outputs'!B14 -> 500
A16: Electricity | C16: =(1/'IRR inputs & outputs'!$B$8)*$B$3*'IRR inputs & outputs'!$B$9+'IRR inputs & outputs'!$B$10 -> 2586.5053 | D16: =(1/'IRR inputs & outputs'!$B$8)*$B$3*'IRR inputs & outputs'!$B$9+'IRR inputs & outputs'!$B$10 -> 2586.5053 | E16: =(1/'IRR inputs & outputs'!$B$8)*$B$3*'IRR inputs & outputs'!$B$9+'IRR inputs & outputs'!$B$10 -> 2586.5053 | F16: =(1/'IRR inputs & outputs'!$B$8)*$B$3*'IRR inputs & outputs'!$B$9+'IRR inputs & outputs'!$B$10 -> 2586.5053 | G16: =(1/'IRR inputs & outputs'!$B$8)*$B$3*'IRR inputs & outputs'!$B$9+'IRR inputs & outputs'!$B$10 -> 2586.5053 | H16: =(1/'IRR inputs & outputs'!$B$8)*$B$3*'IRR inputs & outputs'!$B$9+'IRR inputs & outputs'!$B$10 -> 2586.5053 | I16: =(1/'IRR inputs & outputs'!$B$8)*$B$3*'IRR inputs & outputs'!$B$9+'IRR inputs & outputs'!$B$10 -> 2586.5053 | J16: =(1/'IRR inputs & outputs'!$B$8)*$B$3*'IRR inputs & outputs'!$B$9+'IRR inputs & outputs'!$B$10 -> 2586.5053 | ... L16: =(1/'IRR inputs & outputs'!$B$8)*$B$3*'IRR inputs & outputs'!$B$9+'IRR inputs & outputs'!$B$10 -> 2586.5053
A17: Software - fixed | C17: ='IRR inputs & outputs'!$B$12 -> 300 | D17: ='IRR inputs & outputs'!$B$12 -> 300 | E17: ='IRR inputs & outputs'!$B$12 -> 300 | F17: ='IRR inputs & outputs'!$B$12 -> 300 | G17: ='IRR inputs & outputs'!$B$12 -> 300 | H17: ='IRR inputs & outputs'!$B$12 -> 300 | I17: ='IRR inputs & outputs'!$B$12 -> 300 | J17: ='IRR inputs & outputs'!$B$12 -> 300 | ... L17: ='IRR inputs & outputs'!$B$12 -> 300
A18: Software - variable | C18: =$B$3*'IRR inputs & outputs'!$B$11*'IRR inputs & outputs'!$B$13 -> 414.64912 | D18: =$B$3*'IRR inputs & outputs'!$B$11*'IRR inputs & outputs'!$B$13 -> 414.64912 | E18: =$B$3*'IRR inputs & outputs'!$B$11*'IRR inputs & outputs'!$B$13 -> 414.64912 | F18: =$B$3*'IRR inputs & outputs'!$B$11*'IRR inputs & outputs'!$B$13 -> 414.64912 | G18: =$B$3*'IRR inputs & outputs'!$B$11*'IRR inputs & outputs'!$B$13 -> 414.64912 | H18: =$B$3*'IRR inputs & outputs'!$B$11*'IRR inputs & outputs'!$B$13 -> 414.64912 | I18: =$B$3*'IRR inputs & outputs'!$B$11*'IRR inputs & outputs'!$B$13 -> 414.64912 | J18: =$B$3*'IRR inputs & outputs'!$B$11*'IRR inputs & outputs'!$B$13 -> 414.64912 | ... L18: =$B$3*'IRR inputs & outputs'!$B$11*'IRR inputs & outputs'!$B$13 -> 414.64912
A19: Total outgoings | B19: =SUM(B12:B18) -> 500 | C19: =SUM(C12:C18) -> 4551.1544 | D19: =SUM(D12:D18) -> 4551.1544 | E19: =SUM(E12:E18) -> 4551.1544 | F19: =SUM(F12:F18) -> 4551.1544 | G19: =SUM(G12:G18) -> 7551.1544 | H19: =SUM(H12:H18) -> 4551.1544 | I19: =SUM(I12:I18) -> 4551.1544 | ... L19: =SUM(L12:L18) -> 4551.1544
A21: Total | B21: =B9-B19 -> -500 | C21: =C9-C19 -> 977.50061 | D21: =D9-D19 -> 977.50061 | E21: =E9-E19 -> 977.50061 | F21: =F9-F19 -> 977.50061 | G21: =G9-G19 -> -2022.4994 | H21: =H9-H19 -> 977.50061 | I21: =I9-I19 -> 977.50061 | ... L21: =L9-L19 -> 977.50061
A23: IRR | B23: =IFERROR(IRR(B21:L21),NA()) -> 1.8993305
A25: Subsidy effect
A26: Subsidy | B26: 0.1
A27: Subsidised capex | B27: =$B$12*(1-B26) -> 0
A28: Cashflow | B28: =-B27 -> 0 | C28: =$C$21 -> 977.50061 | D28: =$D$21 -> 977.50061 | E28: =$E$21 -> 977.50061 | F28: =$F$21 -> 977.50061 | G28: =$G$21 -> -2022.4994 | H28: =$H$21 -> 977.50061 | I28: =$I$21 -> 977.50061 | J28: =$J$21 -> 977.50061 | K28: =$K$21 -> 977.50061 | L28: =$L$21 -> 977.50061
A29: IRR | B29: =IFERROR(IRR(B28:L28),NA()) -> #N/A
A31: Subsidy | B31: 0.15
A32: Subsidised capex | B32: =$B$12*(1-B31) -> 0
A33: Cashflow | B33: =-B32 -> 0 | C33: =$C$21 -> 977.50061 | D33: =$D$21 -> 977.50061 | E33: =$E$21 -> 977.50061 | F33: =$F$21 -> 977.50061 | G33: =$G$21 -> -2022.4994 | H33: =$H$21 -> 977.50061 | I33: =$I$21 -> 977.50061 | J33: =$J$21 -> 977.50061 | K33: =$K$21 -> 977.50061 | L33: =$L$21 -> 977.50061
A34: IRR | B34: =IFERROR(IRR(B33:L33),NA()) -> #N/A
A36: Subsidy | B36: 0.2
A37: Subsidised capex | B37: =$B$12*(1-B36) -> 0
A38: Cashflow | B38: =-B37 -> 0 | C38: =$C$21 -> 977.50061 | D38: =$D$21 -> 977.50061 | E38: =$E$21 -> 977.50061 | F38: =$F$21 -> 977.50061 | G38: =$G$21 -> -2022.4994 | H38: =$H$21 -> 977.50061 | I38: =$I$21 -> 977.50061 | J38: =$J$21 -> 977.50061 | K38: =$K$21 -> 977.50061 | L38: =$L$21 -> 977.50061
A39: IRR | B39: =IFERROR(IRR(B38:L38),NA()) -> #N/A
A41: Subsidy | B41: 0.25
A42: Subsidised capex | B42: =$B$12*(1-B41) -> 0
A43: Cashflow | B43: =-B42 -> 0 | C43: =$C$21 -> 977.50061 | D43: =$D$21 -> 977.50061 | E43: =$E$21 -> 977.50061 | F43: =$F$21 -> 977.50061 | G43: =$G$21 -> -2022.4994 | H43: =$H$21 -> 977.50061 | I43: =$I$21 -> 977.50061 | J43: =$J$21 -> 977.50061 | K43: =$K$21 -> 977.50061 | L43: =$L$21 -> 977.50061
A44: IRR | B44: =IFERROR(IRR(B43:L43),NA()) -> #N/A
A46: Subsidy | B46: 0.3
A47: Subsidised capex | B47: =$B$12*(1-B46) -> 0
A48: Cashflow | B48: =-B47 -> 0 | C48: =$C$21 -> 977.50061 | D48: =$D$21 -> 977.50061 | E48: =$E$21 -> 977.50061 | F48: =$F$21 -> 977.50061 | G48: =$G$21 -> -2022.4994 | H48: =$H$21 -> 977.50061 | I48: =$I$21 -> 977.50061 | J48: =$J$21 -> 977.50061 | K48: =$K$21 -> 977.50061 | L48: =$L$21 -> 977.50061
A49: IRR | B49: =IFERROR(IRR(B48:L48),NA()) -> #N/A
A51: Subsidy | B51: 0.35
...

Sheet 15% utilisation
A1: Utilisation | B1: 0.15
A2: Hours in year | B2: =24*365 -> 8760
A3: Energy delivered | B3: =B2*B1*'IRR inputs & outputs'!B2*'IRR inputs & outputs'!B3*'IRR inputs & outputs'!$B$7 -> 14743.08 | C3: kWh p.a.
A5: Year | B5: 0 | C5: 1 | D5: 2 | E5: 3 | F5: 4 | G5: 5 | H5: 6 | I5: 7 | J5: 8 | K5: 9 | L5: 10
A6: Income
A7: Charging | C7: =$B$3*'IRR inputs & outputs'!$B$13 -> 6634.386 | D7: =$B$3*'IRR inputs & outputs'!$B$13 -> 6634.386 | E7: =$B$3*'IRR inputs & outputs'!$B$13 -> 6634.386 | F7: =$B$3*'IRR inputs & outputs'!$B$13 -> 6634.386 | G7: =$B$3*'IRR inputs & outputs'!$B$13 -> 6634.386 | H7: =$B$3*'IRR inputs & outputs'!$B$13 -> 6634.386 | I7: =$B$3*'IRR inputs & outputs'!$B$13 -> 6634.386 | J7: =$B$3*'IRR inputs & outputs'!$B$13 -> 6634.386 | ... L7: =$B$3*'IRR inputs & outputs'!$B$13 -> 6634.386
A9: Total income | C9: =SUM(C7:C8) -> 6634.386 | D9: =SUM(D7:D8) -> 6634.386 | E9: =SUM(E7:E8) -> 6634.386 | F9: =SUM(F7:F8) -> 6634.386 | G9: =SUM(G7:G8) -> 6634.386 | H9: =SUM(H7:H8) -> 6634.386 | I9: =SUM(I7:I8) -> 6634.386 | J9: =SUM(J7:J8) -> 6634.386 | ... L9: =SUM(L7:L8) -> 6634.386
A11: Outgoing
A12: Capex | B12: ='IRR inputs & outputs'!B6 -> 0 | G12: ='IRR inputs & outputs'!B15 -> 3000
A13: Site establishment | B13: ='IRR inputs & outputs'!B16 -> 500
A14: Site license | C14: ='IRR inputs & outputs'!$B$17 -> 750 | D14: ='IRR inputs & outputs'!$B$17 -> 750 | E14: ='IRR inputs & outputs'!$B$17 -> 750 | F14: ='IRR inputs & outputs'!$B$17 -> 750 | G14: ='IRR inputs & outputs'!$B$17 -> 750 | H14: ='IRR inputs & outputs'!$B$17 -> 750 | I14: ='IRR inputs & outputs'!$B$17 -> 750 | J14: ='IRR inputs & outputs'!$B$17 -> 750 | ... L14: ='IRR inputs & outputs'!$B$17 -> 750
A15: Maintenance | C15: ='IRR inputs & outputs'!B14 -> 500 | D15: ='IRR inputs & outputs'!B14 -> 500 | E15: ='IRR inputs & outputs'!B14 -> 500 | F15: ='IRR inputs & outputs'!B14 -> 500 | G15: ='IRR inputs & outputs'!B14 -> 500 | H15: ='IRR inputs & outputs'!B14 -> 500 | I15: ='IRR inputs & outputs'!B14 -> 500 | J15: ='IRR inputs & outputs'!B14 -> 500 | K15: ='IRR inputs & outputs'!B14 -> 500 | L15: ='IRR inputs & outputs'!B14 -> 500
A16: Electricity | C16: =(1/'IRR inputs & outputs'!$B$8)*$B$3*'IRR inputs & outputs'!$B$9+'IRR inputs & outputs'!$B$10 -> 3103.8063 | D16: =(1/'IRR inputs & outputs'!$B$8)*$B$3*'IRR inputs & outputs'!$B$9+'IRR inputs & outputs'!$B$10 -> 3103.8063 | E16: =(1/'IRR inputs & outputs'!$B$8)*$B$3*'IRR inputs & outputs'!$B$9+'IRR inputs & outputs'!$B$10 -> 3103.8063 | F16: =(1/'IRR inputs & outputs'!$B$8)*$B$3*'IRR inputs & outputs'!$B$9+'IRR inputs & outputs'!$B$10 -> 3103.8063 | G16: =(1/'IRR inputs & outputs'!$B$8)*$B$3*'IRR inputs & outputs'!$B$9+'IRR inputs & outputs'!$B$10 -> 3103.8063 | H16: =(1/'IRR inputs & outputs'!$B$8)*$B$3*'IRR inputs & outputs'!$B$9+'IRR inputs & outputs'!$B$10 -> 3103.8063 | I16: =(1/'IRR inputs & outputs'!$B$8)*$B$3*'IRR inputs & outputs'!$B$9+'IRR inputs & outputs'!$B$10 -> 3103.8063 | J16: =(1/'IRR inputs & outputs'!$B$8)*$B$3*'IRR inputs & outputs'!$B$9+'IRR inputs & outputs'!$B$10 -> 3103.8063 | ... L16: =(1/'IRR inputs & outputs'!$B$8)*$B$3*'IRR inputs & outputs'!$B$9+'IRR inputs & outputs'!$B$10 -> 3103.8063
A17: Software - fixed | C17: ='IRR inputs & outputs'!$B$12 -> 300 | D17: ='IRR inputs & outputs'!$B$12 -> 300 | E17: ='IRR inputs & outputs'!$B$12 -> 300 | F17: ='IRR inputs & outputs'!$B$12 -> 300 | G17: ='IRR inputs & outputs'!$B$12 -> 300 | H17: ='IRR inputs & outputs'!$B$12 -> 300 | I17: ='IRR inputs & outputs'!$B$12 -> 300 | J17: ='IRR inputs & outputs'!$B$12 -> 300 | ... L17: ='IRR inputs & outputs'!$B$12 -> 300
A18: Software - variable | C18: =$B$3*'IRR inputs & outputs'!$B$11*'IRR inputs & outputs'!$B$13 -> 497.57895 | D18: =$B$3*'IRR inputs & outputs'!$B$11*'IRR inputs & outputs'!$B$13 -> 497.57895 | E18: =$B$3*'IRR inputs & outputs'!$B$11*'IRR inputs & outputs'!$B$13 -> 497.57895 | F18: =$B$3*'IRR inputs & outputs'!$B$11*'IRR inputs & outputs'!$B$13 -> 497.57895 | G18: =$B$3*'IRR inputs & outputs'!$B$11*'IRR inputs & outputs'!$B$13 -> 497.57895 | H18: =$B$3*'IRR inputs & outputs'!$B$11*'IRR inputs & outputs'!$B$13 -> 497.57895 | I18: =$B$3*'IRR inputs & outputs'!$B$11*'IRR inputs & outputs'!$B$13 -> 497.57895 | J18: =$B$3*'IRR inputs & outputs'!$B$11*'IRR inputs & outputs'!$B$13 -> 497.57895 | ... L18: =$B$3*'IRR inputs & outputs'!$B$11*'IRR inputs & outputs'!$B$13 -> 497.57895
A19: Total outgoings | B19: =SUM(B12:B18) -> 500 | C19: =SUM(C12:C18) -> 5151.3853 | D19: =SUM(D12:D18) -> 5151.3853 | E19: =SUM(E12:E18) -> 5151.3853 | F19: =SUM(F12:F18) -> 5151.3853 | G19: =SUM(G12:G18) -> 8151.3853 | H19: =SUM(H12:H18) -> 5151.3853 | I19: =SUM(I12:I18) -> 5151.3853 | ... L19: =SUM(L12:L18) -> 5151.3853
A21: Total | B21: =B9-B19 -> -500 | C21: =C9-C19 -> 1483.0007 | D21: =D9-D19 -> 1483.0007 | E21: =E9-E19 -> 1483.0007 | F21: =F9-F19 -> 1483.0007 | G21: =G9-G19 -> -1516.9993 | H21: =H9-H19 -> 1483.0007 | I21: =I9-I19 -> 1483.0007 | ... L21: =L9-L19 -> 1483.0007
A23: IRR | B23: =IFERROR(IRR(B21:L21),NA()) -> 2.9475492
A25: Subsidy effect
A26: Subsidy | B26: 0.1
A27: Subsidised capex | B27: =$B$12*(1-B26) -> 0
A28: Cashflow | B28: =-B27 -> 0 | C28: =$C$21 -> 1483.0007 | D28: =$D$21 -> 1483.0007 | E28: =$E$21 -> 1483.0007 | F28: =$F$21 -> 1483.0007 | G28: =$G$21 -> -1516.9993 | H28: =$H$21 -> 1483.0007 | I28: =$I$21 -> 1483.0007 | J28: =$J$21 -> 1483.0007 | K28: =$K$21 -> 1483.0007 | L28: =$L$21 -> 1483.0007
A29: IRR | B29: =IFERROR(IRR(B28:L28),NA()) -> #N/A
A31: Subsidy | B31: 0.15
A32: Subsidised capex | B32: =$B$12*(1-B31) -> 0
A33: Cashflow | B33: =-B32 -> 0 | C33: =$C$21 -> 1483.0007 | D33: =$D$21 -> 1483.0007 | E33: =$E$21 -> 1483.0007 | F33: =$F$21 -> 1483.0007 | G33: =$G$21 -> -1516.9993 | H33: =$H$21 -> 1483.0007 | I33: =$I$21 -> 1483.0007 | J33: =$J$21 -> 1483.0007 | K33: =$K$21 -> 1483.0007 | L33: =$L$21 -> 1483.0007
A34: IRR | B34: =IFERROR(IRR(B33:L33),NA()) -> #N/A
A36: Subsidy | B36: 0.2
A37: Subsidised capex | B37: =$B$12*(1-B36) -> 0
A38: Cashflow | B38: =-B37 -> 0 | C38: =$C$21 -> 1483.0007 | D38: =$D$21 -> 1483.0007 | E38: =$E$21 -> 1483.0007 | F38: =$F$21 -> 1483.0007 | G38: =$G$21 -> -1516.9993 | H38: =$H$21 -> 1483.0007 | I38: =$I$21 -> 1483.0007 | J38: =$J$21 -> 1483.0007 | K38: =$K$21 -> 1483.0007 | L38: =$L$21 -> 1483.0007
A39: IRR | B39: =IFERROR(IRR(B38:L38),NA()) -> #N/A
A41: Subsidy | B41: 0.25
A42: Subsidised capex | B42: =$B$12*(1-B41) -> 0
A43: Cashflow | B43: =-B42 -> 0 | C43: =$C$21 -> 1483.0007 | D43: =$D$21 -> 1483.0007 | E43: =$E$21 -> 1483.0007 | F43: =$F$21 -> 1483.0007 | G43: =$G$21 -> -1516.9993 | H43: =$H$21 -> 1483.0007 | I43: =$I$21 -> 1483.0007 | J43: =$J$21 -> 1483.0007 | K43: =$K$21 -> 1483.0007 | L43: =$L$21 -> 1483.0007
A44: IRR | B44: =IFERROR(IRR(B43:L43),NA()) -> #N/A
A46: Subsidy | B46: 0.3
A47: Subsidised capex | B47: =$B$12*(1-B46) -> 0
A48: Cashflow | B48: =-B47 -> 0 | C48: =$C$21 -> 1483.0007 | D48: =$D$21 -> 1483.0007 | E48: =$E$21 -> 1483.0007 | F48: =$F$21 -> 1483.0007 | G48: =$G$21 -> -1516.9993 | H48: =$H$21 -> 1483.0007 | I48: =$I$21 -> 1483.0007 | J48: =$J$21 -> 1483.0007 | K48: =$K$21 -> 1483.0007 | L48: =$L$21 -> 1483.0007
A49: IRR | B49: =IFERROR(IRR(B48:L48),NA()) -> #N/A
A51: Subsidy | B51: 0.35
...

Sheet 17.5% utilisation
A1: Utilisation | B1: 0.175
A2: Hours in year | B2: =24*365 -> 8760
A3: Energy delivered | B3: =B2*B1*'IRR inputs & outputs'!B2*'IRR inputs & outputs'!B3*'IRR inputs & outputs'!$B$7 -> 17200.26 | C3: kWh p.a.
A5: Year | B5: 0 | C5: 1 | D5: 2 | E5: 3 | F5: 4 | G5: 5 | H5: 6 | I5: 7 | J5: 8 | K5: 9 | L5: 10
A6: Income
A7: Charging | C7: =$B$3*'IRR inputs & outputs'!$B$13 -> 7740.117 | D7: =$B$3*'IRR inputs & outputs'!$B$13 -> 7740.117 | E7: =$B$3*'IRR inputs & outputs'!$B$13 -> 7740.117 | F7: =$B$3*'IRR inputs & outputs'!$B$13 -> 7740.117 | G7: =$B$3*'IRR inputs & outputs'!$B$13 -> 7740.117 | H7: =$B$3*'IRR inputs & outputs'!$B$13 -> 7740.117 | I7: =$B$3*'IRR inputs & outputs'!$B$13 -> 7740.117 | J7: =$B$3*'IRR inputs & outputs'!$B$13 -> 7740.117 | ... L7: =$B$3*'IRR inputs & outputs'!$B$13 -> 7740.117
A9: Total income | C9: =SUM(C7:C8) -> 7740.117 | D9: =SUM(D7:D8) -> 7740.117 | E9: =SUM(E7:E8) -> 7740.117 | F9: =SUM(F7:F8) -> 7740.117 | G9: =SUM(G7:G8) -> 7740.117 | H9: =SUM(H7:H8) -> 7740.117 | I9: =SUM(I7:I8) -> 7740.117 | J9: =SUM(J7:J8) -> 7740.117 | ... L9: =SUM(L7:L8) -> 7740.117
A11: Outgoing
A12: Capex | B12: ='IRR inputs & outputs'!B6 -> 0 | G12: ='IRR inputs & outputs'!B15 -> 3000
A13: Site establishment | B13: ='IRR inputs & outputs'!B16 -> 500
A14: Site license | C14: ='IRR inputs & outputs'!$B$17 -> 750 | D14: ='IRR inputs & outputs'!$B$17 -> 750 | E14: ='IRR inputs & outputs'!$B$17 -> 750 | F14: ='IRR inputs & outputs'!$B$17 -> 750 | G14: ='IRR inputs & outputs'!$B$17 -> 750 | H14: ='IRR inputs & outputs'!$B$17 -> 750 | I14: ='IRR inputs & outputs'!$B$17 -> 750 | J14: ='IRR inputs & outputs'!$B$17 -> 750 | ... L14: ='IRR inputs & outputs'!$B$17 -> 750
A15: Maintenance | C15: ='IRR inputs & outputs'!B14 -> 500 | D15: ='IRR inputs & outputs'!B14 -> 500 | E15: ='IRR inputs & outputs'!B14 -> 500 | F15: ='IRR inputs & outputs'!B14 -> 500 | G15: ='IRR inputs & outputs'!B14 -> 500 | H15: ='IRR inputs & outputs'!B14 -> 500 | I15: ='IRR inputs & outputs'!B14 -> 500 | J15: ='IRR inputs & outputs'!B14 -> 500 | K15: ='IRR inputs & outputs'!B14 -> 500 | L15: ='IRR inputs & outputs'!B14 -> 500
A16: Electricity | C16: =(1/'IRR inputs & outputs'!$B$8)*$B$3*'IRR inputs & outputs'!$B$9+'IRR inputs & outputs'!$B$10 -> 3621.1074 | D16: =(1/'IRR inputs & outputs'!$B$8)*$B$3*'IRR inputs & outputs'!$B$9+'IRR inputs & outputs'!$B$10 -> 3621.1074 | E16: =(1/'IRR inputs & outputs'!$B$8)*$B$3*'IRR inputs & outputs'!$B$9+'IRR inputs & outputs'!$B$10 -> 3621.1074 | F16: =(1/'IRR inputs & outputs'!$B$8)*$B$3*'IRR inputs & outputs'!$B$9+'IRR inputs & outputs'!$B$10 -> 3621.1074 | G16: =(1/'IRR inputs & outputs'!$B$8)*$B$3*'IRR inputs & outputs'!$B$9+'IRR inputs & outputs'!$B$10 -> 3621.1074 | H16: =(1/'IRR inputs & outputs'!$B$8)*$B$3*'IRR inputs & outputs'!$B$9+'IRR inputs & outputs'!$B$10 -> 3621.1074 | I16: =(1/'IRR inputs & outputs'!$B$8)*$B$3*'IRR inputs & outputs'!$B$9+'IRR inputs & outputs'!$B$10 -> 3621.1074 | J16: =(1/'IRR inputs & outputs'!$B$8)*$B$3*'IRR inputs & outputs'!$B$9+'IRR inputs & outputs'!$B$10 -> 3621.1074 | ... L16: =(1/'IRR inputs & outputs'!$B$8)*$B$3*'IRR inputs & outputs'!$B$9+'IRR inputs & outputs'!$B$10 -> 3621.1074
A17: Software - fixed | C17: ='IRR inputs & outputs'!$B$12 -> 300 | D17: ='IRR inputs & outputs'!$B$12 -> 300 | E17: ='IRR inputs & outputs'!$B$12 -> 300 | F17: ='IRR inputs & outputs'!$B$12 -> 300 | G17: ='IRR inputs & outputs'!$B$12 -> 300 | H17: ='IRR inputs & outputs'!$B$12 -> 300 | I17: ='IRR inputs & outputs'!$B$12 -> 300 | J17: ='IRR inputs & outputs'!$B$12 -> 300 | ... L17: ='IRR inputs & outputs'!$B$12 -> 300
A18: Software - variable | C18: =$B$3*'IRR inputs & outputs'!$B$11*'IRR inputs & outputs'!$B$13 -> 580.50878 | D18: =$B$3*'IRR inputs & outputs'!$B$11*'IRR inputs & outputs'!$B$13 -> 580.50878 | E18: =$B$3*'IRR inputs & outputs'!$B$11*'IRR inputs & outputs'!$B$13 -> 580.50878 | F18: =$B$3*'IRR inputs & outputs'!$B$11*'IRR inputs & outputs'!$B$13 -> 580.50878 | G18: =$B$3*'IRR inputs & outputs'!$B$11*'IRR inputs & outputs'!$B$13 -> 580.50878 | H18: =$B$3*'IRR inputs & outputs'!$B$11*'IRR inputs & outputs'!$B$13 -> 580.50878 | I18: =$B$3*'IRR inputs & outputs'!$B$11*'IRR inputs & outputs'!$B$13 -> 580.50878 | J18: =$B$3*'IRR inputs & outputs'!$B$11*'IRR inputs & outputs'!$B$13 -> 580.50878 | ... L18: =$B$3*'IRR inputs & outputs'!$B$11*'IRR inputs & outputs'!$B$13 -> 580.50878
A19: Total outgoings | B19: =SUM(B12:B18) -> 500 | C19: =SUM(C12:C18) -> 5751.6161 | D19: =SUM(D12:D18) -> 5751.6161 | E19: =SUM(E12:E18) -> 5751.6161 | F19: =SUM(F12:F18) -> 5751.6161 | G19: =SUM(G12:G18) -> 8751.6161 | H19: =SUM(H12:H18) -> 5751.6161 | I19: =SUM(I12:I18) -> 5751.6161 | ... L19: =SUM(L12:L18) -> 5751.6161
A21: Total | B21: =B9-B19 -> -500 | C21: =C9-C19 -> 1988.5009 | D21: =D9-D19 -> 1988.5009 | E21: =E9-E19 -> 1988.5009 | F21: =F9-F19 -> 1988.5009 | G21: =G9-G19 -> -1011.4991 | H21: =H9-H19 -> 1988.5009 | I21: =I9-I19 -> 1988.5009 | ... L21: =L9-L19 -> 1988.5009
A23: IRR | B23: =IFERROR(IRR(B21:L21),NA()) -> 3.9691409
A25: Subsidy effect
A26: Subsidy | B26: 0.1
A27: Subsidised capex | B27: =$B$12*(1-B26) -> 0
A28: Cashflow | B28: =-B27 -> 0 | C28: =$C$21 -> 1988.5009 | D28: =$D$21 -> 1988.5009 | E28: =$E$21 -> 1988.5009 | F28: =$F$21 -> 1988.5009 | G28: =$G$21 -> -1011.4991 | H28: =$H$21 -> 1988.5009 | I28: =$I$21 -> 1988.5009 | J28: =$J$21 -> 1988.5009 | K28: =$K$21 -> 1988.5009 | L28: =$L$21 -> 1988.5009
A29: IRR | B29: =IFERROR(IRR(B28:L28),NA()) -> #N/A
A31: Subsidy | B31: 0.15
A32: Subsidised capex | B32: =$B$12*(1-B31) -> 0
A33: Cashflow | B33: =-B32 -> 0 | C33: =$C$21 -> 1988.5009 | D33: =$D$21 -> 1988.5009 | E33: =$E$21 -> 1988.5009 | F33: =$F$21 -> 1988.5009 | G33: =$G$21 -> -1011.4991 | H33: =$H$21 -> 1988.5009 | I33: =$I$21 -> 1988.5009 | J33: =$J$21 -> 1988.5009 | K33: =$K$21 -> 1988.5009 | L33: =$L$21 -> 1988.5009
A34: IRR | B34: =IFERROR(IRR(B33:L33),NA()) -> #N/A
A36: Subsidy | B36: 0.2
A37: Subsidised capex | B37: =$B$12*(1-B36) -> 0
A38: Cashflow | B38: =-B37 -> 0 | C38: =$C$21 -> 1988.5009 | D38: =$D$21 -> 1988.5009 | E38: =$E$21 -> 1988.5009 | F38: =$F$21 -> 1988.5009 | G38: =$G$21 -> -1011.4991 | H38: =$H$21 -> 1988.5009 | I38: =$I$21 -> 1988.5009 | J38: =$J$21 -> 1988.5009 | K38: =$K$21 -> 1988.5009 | L38: =$L$21 -> 1988.5009
A39: IRR | B39: =IFERROR(IRR(B38:L38),NA()) -> #N/A
A41: Subsidy | B41: 0.25
A42: Subsidised capex | B42: =$B$12*(1-B41) -> 0
A43: Cashflow | B43: =-B42 -> 0 | C43: =$C$21 -> 1988.5009 | D43: =$D$21 -> 1988.5009 | E43: =$E$21 -> 1988.5009 | F43: =$F$21 -> 1988.5009 | G43: =$G$21 -> -1011.4991 | H43: =$H$21 -> 1988.5009 | I43: =$I$21 -> 1988.5009 | J43: =$J$21 -> 1988.5009 | K43: =$K$21 -> 1988.5009 | L43: =$L$21 -> 1988.5009
A44: IRR | B44: =IFERROR(IRR(B43:L43),NA()) -> #N/A
A46: Subsidy | B46: 0.3
A47: Subsidised capex | B47: =$B$12*(1-B46) -> 0
A48: Cashflow | B48: =-B47 -> 0 | C48: =$C$21 -> 1988.5009 | D48: =$D$21 -> 1988.5009 | E48: =$E$21 -> 1988.5009 | F48: =$F$21 -> 1988.5009 | G48: =$G$21 -> -1011.4991 | H48: =$H$21 -> 1988.5009 | I48: =$I$21 -> 1988.5009 | J48: =$J$21 -> 1988.5009 | K48: =$K$21 -> 1988.5009 | L48: =$L$21 -> 1988.5009
A49: IRR | B49: =IFERROR(IRR(B48:L48),NA()) -> #N/A
A51: Subsidy | B51: 0.35
...

Sheet 20% utilisation
A1: Utilisation | B1: 0.2
A2: Hours in year | B2: =24*365 -> 8760
A3: Energy delivered | B3: =B2*B1*'IRR inputs & outputs'!B2*'IRR inputs & outputs'!B3*'IRR inputs & outputs'!$B$7 -> 19657.44 | C3: kWh p.a.
A5: Year | B5: 0 | C5: 1 | D5: 2 | E5: 3 | F5: 4 | G5: 5 | H5: 6 | I5: 7 | J5: 8 | K5: 9 | L5: 10
A6: Income
A7: Charging | C7: =$B$3*'IRR inputs & outputs'!$B$13 -> 8845.848 | D7: =$B$3*'IRR inputs & outputs'!$B$13 -> 8845.848 | E7: =$B$3*'IRR inputs & outputs'!$B$13 -> 8845.848 | F7: =$B$3*'IRR inputs & outputs'!$B$13 -> 8845.848 | G7: =$B$3*'IRR inputs & outputs'!$B$13 -> 8845.848 | H7: =$B$3*'IRR inputs & outputs'!$B$13 -> 8845.848 | I7: =$B$3*'IRR inputs & outputs'!$B$13 -> 8845.848 | J7: =$B$3*'IRR inputs & outputs'!$B$13 -> 8845.848 | ... L7: =$B$3*'IRR inputs & outputs'!$B$13 -> 8845.848
A9: Total income | C9: =SUM(C7:C8) -> 8845.848 | D9: =SUM(D7:D8) -> 8845.848 | E9: =SUM(E7:E8) -> 8845.848 | F9: =SUM(F7:F8) -> 8845.848 | G9: =SUM(G7:G8) -> 8845.848 | H9: =SUM(H7:H8) -> 8845.848 | I9: =SUM(I7:I8) -> 8845.848 | J9: =SUM(J7:J8) -> 8845.848 | ... L9: =SUM(L7:L8) -> 8845.848
A11: Outgoing
A12: Capex | B12: ='IRR inputs & outputs'!B6 -> 0 | G12: ='IRR inputs & outputs'!B15 -> 3000
A13: Site establishment | B13: ='IRR inputs & outputs'!B16 -> 500
A14: Site license | C14: ='IRR inputs & outputs'!$B$17 -> 750 | D14: ='IRR inputs & outputs'!$B$17 -> 750 | E14: ='IRR inputs & outputs'!$B$17 -> 750 | F14: ='IRR inputs & outputs'!$B$17 -> 750 | G14: ='IRR inputs & outputs'!$B$17 -> 750 | H14: ='IRR inputs & outputs'!$B$17 -> 750 | I14: ='IRR inputs & outputs'!$B$17 -> 750 | J14: ='IRR inputs & outputs'!$B$17 -> 750 | ... L14: ='IRR inputs & outputs'!$B$17 -> 750
A15: Maintenance | C15: ='IRR inputs & outputs'!B14 -> 500 | D15: ='IRR inputs & outputs'!B14 -> 500 | E15: ='IRR inputs & outputs'!B14 -> 500 | F15: ='IRR inputs & outputs'!B14 -> 500 | G15: ='IRR inputs & outputs'!B14 -> 500 | H15: ='IRR inputs & outputs'!B14 -> 500 | I15: ='IRR inputs & outputs'!B14 -> 500 | J15: ='IRR inputs & outputs'!B14 -> 500 | K15: ='IRR inputs & outputs'!B14 -> 500 | L15: ='IRR inputs & outputs'!B14 -> 500
A16: Electricity | C16: =(1/'IRR inputs & outputs'!$B$8)*$B$3*'IRR inputs & outputs'!$B$9+'IRR inputs & outputs'!$B$10 -> 4138.4084 | D16: =(1/'IRR inputs & outputs'!$B$8)*$B$3*'IRR inputs & outputs'!$B$9+'IRR inputs & outputs'!$B$10 -> 4138.4084 | E16: =(1/'IRR inputs & outputs'!$B$8)*$B$3*'IRR inputs & outputs'!$B$9+'IRR inputs & outputs'!$B$10 -> 4138.4084 | F16: =(1/'IRR inputs & outputs'!$B$8)*$B$3*'IRR inputs & outputs'!$B$9+'IRR inputs & outputs'!$B$10 -> 4138.4084 | G16: =(1/'IRR inputs & outputs'!$B$8)*$B$3*'IRR inputs & outputs'!$B$9+'IRR inputs & outputs'!$B$10 -> 4138.4084 | H16: =(1/'IRR inputs & outputs'!$B$8)*$B$3*'IRR inputs & outputs'!$B$9+'IRR inputs & outputs'!$B$10 -> 4138.4084 | I16: =(1/'IRR inputs & outputs'!$B$8)*$B$3*'IRR inputs & outputs'!$B$9+'IRR inputs & outputs'!$B$10 -> 4138.4084 | J16: =(1/'IRR inputs & outputs'!$B$8)*$B$3*'IRR inputs & outputs'!$B$9+'IRR inputs & outputs'!$B$10 -> 4138.4084 | ... L16: =(1/'IRR inputs & outputs'!$B$8)*$B$3*'IRR inputs & outputs'!$B$9+'IRR inputs & outputs'!$B$10 -> 4138.4084
A17: Software - fixed | C17: ='IRR inputs & outputs'!$B$12 -> 300 | D17: ='IRR inputs & outputs'!$B$12 -> 300 | E17: ='IRR inputs & outputs'!$B$12 -> 300 | F17: ='IRR inputs & outputs'!$B$12 -> 300 | G17: ='IRR inputs & outputs'!$B$12 -> 300 | H17: ='IRR inputs & outputs'!$B$12 -> 300 | I17: ='IRR inputs & outputs'!$B$12 -> 300 | J17: ='IRR inputs & outputs'!$B$12 -> 300 | ... L17: ='IRR inputs & outputs'!$B$12 -> 300
A18: Software - variable | C18: =$B$3*'IRR inputs & outputs'!$B$11*'IRR inputs & outputs'!$B$13 -> 663.4386 | D18: =$B$3*'IRR inputs & outputs'!$B$11*'IRR inputs & outputs'!$B$13 -> 663.4386 | E18: =$B$3*'IRR inputs & outputs'!$B$11*'IRR inputs & outputs'!$B$13 -> 663.4386 | F18: =$B$3*'IRR inputs & outputs'!$B$11*'IRR inputs & outputs'!$B$13 -> 663.4386 | G18: =$B$3*'IRR inputs & outputs'!$B$11*'IRR inputs & outputs'!$B$13 -> 663.4386 | H18: =$B$3*'IRR inputs & outputs'!$B$11*'IRR inputs & outputs'!$B$13 -> 663.4386 | I18: =$B$3*'IRR inputs & outputs'!$B$11*'IRR inputs & outputs'!$B$13 -> 663.4386 | J18: =$B$3*'IRR inputs & outputs'!$B$11*'IRR inputs & outputs'!$B$13 -> 663.4386 | ... L18: =$B$3*'IRR inputs & outputs'!$B$11*'IRR inputs & outputs'!$B$13 -> 663.4386
A19: Total outgoings | B19: =SUM(B12:B18) -> 500 | C19: =SUM(C12:C18) -> 6351.847 | D19: =SUM(D12:D18) -> 6351.847 | E19: =SUM(E12:E18) -> 6351.847 | F19: =SUM(F12:F18) -> 6351.847 | G19: =SUM(G12:G18) -> 9351.847 | H19: =SUM(H12:H18) -> 6351.847 | I19: =SUM(I12:I18) -> 6351.847 | ... L19: =SUM(L12:L18) -> 6351.847
A21: Total | B21: =B9-B19 -> -500 | C21: =C9-C19 -> 2494.001 | D21: =D9-D19 -> 2494.001 | E21: =E9-E19 -> 2494.001 | F21: =F9-F19 -> 2494.001 | G21: =G9-G19 -> -505.99902 | H21: =H9-H19 -> 2494.001 | I21: =I9-I19 -> 2494.001 | ... L21: =L9-L19 -> 2494.001
A23: IRR | B23: =IFERROR(IRR(B21:L21),NA()) -> 4.9841048
A25: Subsidy effect
A26: Subsidy | B26: 0.1
A27: Subsidised capex | B27: =$B$12*(1-B26) -> 0
A28: Cashflow | B28: =-B27 -> 0 | C28: =$C$21 -> 2494.001 | D28: =$D$21 -> 2494.001 | E28: =$E$21 -> 2494.001 | F28: =$F$21 -> 2494.001 | G28: =$G$21 -> -505.99902 | H28: =$H$21 -> 2494.001 | I28: =$I$21 -> 2494.001 | J28: =$J$21 -> 2494.001 | K28: =$K$21 -> 2494.001 | L28: =$L$21 -> 2494.001
A29: IRR | B29: =IFERROR(IRR(B28:L28),NA()) -> #N/A
A31: Subsidy | B31: 0.15
A32: Subsidised capex | B32: =$B$12*(1-B31) -> 0
A33: Cashflow | B33: =-B32 -> 0 | C33: =$C$21 -> 2494.001 | D33: =$D$21 -> 2494.001 | E33: =$E$21 -> 2494.001 | F33: =$F$21 -> 2494.001 | G33: =$G$21 -> -505.99902 | H33: =$H$21 -> 2494.001 | I33: =$I$21 -> 2494.001 | J33: =$J$21 -> 2494.001 | K33: =$K$21 -> 2494.001 | L33: =$L$21 -> 2494.001
A34: IRR | B34: =IFERROR(IRR(B33:L33),NA()) -> #N/A
A36: Subsidy | B36: 0.2
A37: Subsidised capex | B37: =$B$12*(1-B36) -> 0
A38: Cashflow | B38: =-B37 -> 0 | C38: =$C$21 -> 2494.001 | D38: =$D$21 -> 2494.001 | E38: =$E$21 -> 2494.001 | F38: =$F$21 -> 2494.001 | G38: =$G$21 -> -505.99902 | H38: =$H$21 -> 2494.001 | I38: =$I$21 -> 2494.001 | J38: =$J$21 -> 2494.001 | K38: =$K$21 -> 2494.001 | L38: =$L$21 -> 2494.001
A39: IRR | B39: =IFERROR(IRR(B38:L38),NA()) -> #N/A
A41: Subsidy | B41: 0.25
A42: Subsidised capex | B42: =$B$12*(1-B41) -> 0
A43: Cashflow | B43: =-B42 -> 0 | C43: =$C$21 -> 2494.001 | D43: =$D$21 -> 2494.001 | E43: =$E$21 -> 2494.001 | F43: =$F$21 -> 2494.001 | G43: =$G$21 -> -505.99902 | H43: =$H$21 -> 2494.001 | I43: =$I$21 -> 2494.001 | J43: =$J$21 -> 2494.001 | K43: =$K$21 -> 2494.001 | L43: =$L$21 -> 2494.001
A44: IRR | B44: =IFERROR(IRR(B43:L43),NA()) -> #N/A
A46: Subsidy | B46: 0.3
A47: Subsidised capex | B47: =$B$12*(1-B46) -> 0
A48: Cashflow | B48: =-B47 -> 0 | C48: =$C$21 -> 2494.001 | D48: =$D$21 -> 2494.001 | E48: =$E$21 -> 2494.001 | F48: =$F$21 -> 2494.001 | G48: =$G$21 -> -505.99902 | H48: =$H$21 -> 2494.001 | I48: =$I$21 -> 2494.001 | J48: =$J$21 -> 2494.001 | K48: =$K$21 -> 2494.001 | L48: =$L$21 -> 2494.001
A49: IRR | B49: =IFERROR(IRR(B48:L48),NA()) -> #N/A
A51: Subsidy | B51: 0.35
...

Sheet 22.5% utilisation
A1: Utilisation | B1: 0.225
A2: Hours in year | B2: =24*365 -> 8760
A3: Energy delivered | B3: =B2*B1*'IRR inputs & outputs'!B2*'IRR inputs & outputs'!B3*'IRR inputs & outputs'!$B$7 -> 22114.62 | C3: kWh p.a.
A5: Year | B5: 0 | C5: 1 | D5: 2 | E5: 3 | F5: 4 | G5: 5 | H5: 6 | I5: 7 | J5: 8 | K5: 9 | L5: 10
A6: Income
A7: Charging | C7: =$B$3*'IRR inputs & outputs'!$B$13 -> 9951.579 | D7: =$B$3*'IRR inputs & outputs'!$B$13 -> 9951.579 | E7: =$B$3*'IRR inputs & outputs'!$B$13 -> 9951.579 | F7: =$B$3*'IRR inputs & outputs'!$B$13 -> 9951.579 | G7: =$B$3*'IRR inputs & outputs'!$B$13 -> 9951.579 | H7: =$B$3*'IRR inputs & outputs'!$B$13 -> 9951.579 | I7: =$B$3*'IRR inputs & outputs'!$B$13 -> 9951.579 | J7: =$B$3*'IRR inputs & outputs'!$B$13 -> 9951.579 | ... L7: =$B$3*'IRR inputs & outputs'!$B$13 -> 9951.579
A9: Total income | C9: =SUM(C7:C8) -> 9951.579 | D9: =SUM(D7:D8) -> 9951.579 | E9: =SUM(E7:E8) -> 9951.579 | F9: =SUM(F7:F8) -> 9951.579 | G9: =SUM(G7:G8) -> 9951.579 | H9: =SUM(H7:H8) -> 9951.579 | I9: =SUM(I7:I8) -> 9951.579 | J9: =SUM(J7:J8) -> 9951.579 | ... L9: =SUM(L7:L8) -> 9951.579
A11: Outgoing
A12: Capex | B12: ='IRR inputs & outputs'!B6 -> 0 | G12: ='IRR inputs & outputs'!B15 -> 3000
A13: Site establishment | B13: ='IRR inputs & outputs'!B16 -> 500
A14: Site license | C14: ='IRR inputs & outputs'!$B$17 -> 750 | D14: ='IRR inputs & outputs'!$B$17 -> 750 | E14: ='IRR inputs & outputs'!$B$17 -> 750 | F14: ='IRR inputs & outputs'!$B$17 -> 750 | G14: ='IRR inputs & outputs'!$B$17 -> 750 | H14: ='IRR inputs & outputs'!$B$17 -> 750 | I14: ='IRR inputs & outputs'!$B$17 -> 750 | J14: ='IRR inputs & outputs'!$B$17 -> 750 | ... L14: ='IRR inputs & outputs'!$B$17 -> 750
A15: Maintenance | C15: ='IRR inputs & outputs'!B14 -> 500 | D15: ='IRR inputs & outputs'!B14 -> 500 | E15: ='IRR inputs & outputs'!B14 -> 500 | F15: ='IRR inputs & outputs'!B14 -> 500 | G15: ='IRR inputs & outputs'!B14 -> 500 | H15: ='IRR inputs & outputs'!B14 -> 500 | I15: ='IRR inputs & outputs'!B14 -> 500 | J15: ='IRR inputs & outputs'!B14 -> 500 | K15: ='IRR inputs & outputs'!B14 -> 500 | L15: ='IRR inputs & outputs'!B14 -> 500
